<?xml version="1.0"?>
<robot name="racecar">
    <material name="red">
        <color rgba="0.8 0 0 1"/>
    </material>
    <material name="green">
        <color rgba="0 0.8 0 1"/>
    </material>
    <material name="blue">
        <color rgba="0 0 0.8 1"/>
    </material>

    <link name="body_link">
        <visual>
            <origin xyz="0 0 0" rpy="-1.5708 0 0"/>
            <geometry>
                <box size="1 0.1 0.1"/>
            </geometry>
            <material name="red"/>
        </visual>
        <collision>
            <origin xyz="0 0 0" rpy="-1.5708 0 0"/>
            <geometry>
                <box size="1 0.1 0.1"/>
            </geometry>
            <material name="red"/>
        </collision>
        <inertial>
            <origin xyz="0 0 0"/>
            <mass value="1"/>
            <inertia ixx="1" ixy="0" iyy="1" iyz="0" izz="1" izx="0"/>
        </inertial>
    </link>

    <link name="right_rear_wheel_link">
        <visual>
            <origin xyz="0 0 0" rpy="-1.5708 0 0"/>
            <geometry>
                <cylinder length="0.1" radius="0.2"/>
            </geometry>
            <material name="blue"/>
        </visual>
        <collision>
            <origin xyz="0 0 0" rpy="1.5708 0 0"/>
            <geometry>
                <cylinder length="0.1" radius="0.2"/>
            </geometry>
        </collision>
    </link>

    <link name="left_rear_wheel_link">
        <visual>
            <origin xyz="0 0 0" rpy="1.5708 0 0"/>
            <geometry>
                <cylinder length="0.1" radius="0.2"/>
            </geometry>
            <material name="blue"/>
        </visual>
        <collision>
            <origin xyz="0 0 0" rpy="1.5708 0 0"/>
            <geometry>
                <cylinder length="0.1" radius="0.2"/>
            </geometry>
        </collision>
    </link>

    <link name="right_front_wheel_link">
        <visual>
            <origin xyz="0 0 0" rpy="-1.5708 0 0"/>
            <geometry>
                <cylinder length="0.05" radius="0.1"/>
            </geometry>
            <material name="green"/>
        </visual>
        <collision>
            <origin xyz="0 0 0" rpy="1.5708 0 0"/>
            <geometry>
                <cylinder length="0.05" radius="0.1"/>
            </geometry>
        </collision>
    </link>

    <link name="left_front_wheel_link">
        <visual>
            <origin xyz="0 0 0" rpy="1.5708 0 0"/>
            <geometry>
                <cylinder length="0.05" radius="0.1"/>
            </geometry>
            <material name="green"/>
        </visual>
        <collision>
            <origin xyz="0 0 0" rpy="1.5708 0 0"/>
            <geometry>
                <cylinder length="0.05" radius="0.1"/>
            </geometry>
        </collision>
    </link>

    <joint name="right_rear_wheel_joint" type="continuous">
        <parent link="body_link"/>
        <child link="right_rear_wheel_link"/>
        <origin xyz="-0.5 -0.2 0"/>
        <axis xyz="0 1 0"/>
    </joint>

    <joint name="left_rear_wheel_joint" type="continuous">
        <parent link="body_link"/>
        <child link="left_rear_wheel_link"/>
        <origin xyz="-0.5 0.2 0"/>
        <axis xyz="0 1 0"/>
    </joint>

    <joint name="right_front_wheel_joint" type="continuous">
        <parent link="body_link"/>
        <child link="right_front_wheel_link"/>
        <origin xyz="0.5 -0.1 0"/>
        <axis xyz="0 1 0"/>
    </joint>

    <joint name="left_front_wheel_joint" type="continuous">
        <parent link="body_link"/>
        <child link="left_front_wheel_link"/>
        <origin xyz="0.5 0.1 0"/>
        <axis xyz="0 1 0"/>
    </joint>
</robot>
